<?xml version="1.0" ?>
<robot name="converted_robot">
   <!--generated with mjcf_urdf_simple_converter (https://github.com/Yasu31/mjcf_urdf_simple_converter)-->
   <link name="world">
      <inertial>
         <origin xyz="0.0 0.0 0.0" rpy="0.0 0.0 0.0"/>
         <mass value="0.0"/>
         <inertia ixx="0.0" iyy="0.0" izz="0.0" ixy="0" ixz="0" iyz="0"/>
      </inertial>
   </link>
   <link name="Pelvis">
      <inertial>
         <origin xyz="-0.0055 -0.0 -0.0121" rpy="0.0 0.0 0.0"/>
         <mass value="5.12487152"/>
         <inertia ixx="0.028426722761661336" iyy="0.020673458385198937" izz="0.031290090977315735" ixy="0" ixz="0" iyz="0"/>
      </inertial>
   </link>
   <!-- Floating base joint for the humanoid -->
   <joint type="floating" name="Pelvis">
      <parent link="world"/>
      <child link="Pelvis"/>
      <origin xyz="-0.0018 -0.2233 0.0282" rpy="0 0 0"/>
   </joint>
   <link name="L_Hip">
      <inertial>
         <origin xyz="-0.00225 0.01715 -0.18760000000000002" rpy="0.09077999770182904 0.011939407238161115 0.0005423085872250585"/>
         <mass value="7.472438075928378"/>
         <inertia ixx="0.06736051601680927" iyy="0.06736051601680927" izz="0.013379227410639313" ixy="0" ixz="0" iyz="0"/>
      </inertial>
   </link>
   <link name="L_Hip_x_jointbody">
      <inertial>
         <origin xyz="0.0 0.0 0.0" rpy="0.0 0.0 0.0"/>
         <mass value="0.001"/>
         <inertia ixx="1e-09" iyy="1e-09" izz="1e-09" ixy="0" ixz="0" iyz="0"/>
      </inertial>
   </link>
   <joint type="revolute" name="L_Hip_x">
      <parent link="Pelvis"/>
      <child link="L_Hip_x_jointbody"/>
      <origin xyz="-0.0068 0.0695 -0.0914" rpy="0.0 0.0 0.0"/>
      <axis xyz="1.0 0.0 0.0"/>
      <limit lower="-3.141592653589793" upper="3.141592653589793" effort="100" velocity="100"/>
   </joint>
   <link name="L_Hip_y_jointbody">
      <inertial>
         <origin xyz="0.0 0.0 0.0" rpy="0.0 0.0 0.0"/>
         <mass value="0.001"/>
         <inertia ixx="1e-09" iyy="1e-09" izz="1e-09" ixy="0" ixz="0" iyz="0"/>
      </inertial>
   </link>
   <joint type="revolute" name="L_Hip_y">
      <parent link="L_Hip_x_jointbody"/>
      <child link="L_Hip_y_jointbody"/>
      <origin xyz="0.0 0.0 0.0" rpy="0.0 0.0 0.0"/>
      <axis xyz="0.0 1.0 0.0"/>
      <limit lower="-3.141592653589793" upper="3.141592653589793" effort="100" velocity="100"/>
   </joint>
   <link name="L_Hip_z_jointbody">
      <inertial>
         <origin xyz="0.0 0.0 0.0" rpy="0.0 0.0 0.0"/>
         <mass value="0.001"/>
         <inertia ixx="1e-09" iyy="1e-09" izz="1e-09" ixy="0" ixz="0" iyz="0"/>
      </inertial>
   </link>
   <joint type="revolute" name="L_Hip_z">
      <parent link="L_Hip_y_jointbody"/>
      <child link="L_Hip_z_jointbody"/>
      <origin xyz="0.0 0.0 0.0" rpy="0.0 0.0 0.0"/>
      <axis xyz="0.0 0.0 1.0"/>
      <limit lower="-3.141592653589793" upper="3.141592653589793" effort="100" velocity="100"/>
   </joint>
   <joint type="fixed" name="L_Hip_z_offset">
      <parent link="L_Hip_z_jointbody"/>
      <child link="L_Hip"/>
      <origin xyz="-0.0 -0.0 -0.0" rpy="0.0 0.0 0.0"/>
   </joint>
   <link name="L_Knee">
      <inertial>
         <origin xyz="-0.02185 -0.0068000000000000005 -0.199" rpy="-0.03432487161809833 0.10962782974264984 -0.0018835515816885834"/>
         <mass value="3.547588285372635"/>
         <inertia ixx="0.03191742710881817" iyy="0.03191742710881817" izz="0.004951901546606483" ixy="0" ixz="0" iyz="0"/>
      </inertial>
   </link>
   <link name="L_Knee_x_jointbody">
      <inertial>
         <origin xyz="0.0 0.0 0.0" rpy="0.0 0.0 0.0"/>
         <mass value="0.001"/>
         <inertia ixx="1e-09" iyy="1e-09" izz="1e-09" ixy="0" ixz="0" iyz="0"/>
      </inertial>
   </link>
   <joint type="revolute" name="L_Knee_x">
      <parent link="L_Hip"/>
      <child link="L_Knee_x_jointbody"/>
      <origin xyz="-0.0045 0.0343 -0.3752" rpy="0.0 0.0 0.0"/>
      <axis xyz="1.0 0.0 0.0"/>
      <limit lower="-3.141592653589793" upper="3.141592653589793" effort="100" velocity="100"/>
   </joint>
   <link name="L_Knee_y_jointbody">
      <inertial>
         <origin xyz="0.0 0.0 0.0" rpy="0.0 0.0 0.0"/>
         <mass value="0.001"/>
         <inertia ixx="1e-09" iyy="1e-09" izz="1e-09" ixy="0" ixz="0" iyz="0"/>
      </inertial>
   </link>
   <joint type="revolute" name="L_Knee_y">
      <parent link="L_Knee_x_jointbody"/>
      <child link="L_Knee_y_jointbody"/>
      <origin xyz="0.0 0.0 0.0" rpy="0.0 0.0 0.0"/>
      <axis xyz="0.0 1.0 0.0"/>
      <limit lower="-3.141592653589793" upper="3.141592653589793" effort="100" velocity="100"/>
   </joint>
   <link name="L_Knee_z_jointbody">
      <inertial>
         <origin xyz="0.0 0.0 0.0" rpy="0.0 0.0 0.0"/>
         <mass value="0.001"/>
         <inertia ixx="1e-09" iyy="1e-09" izz="1e-09" ixy="0" ixz="0" iyz="0"/>
      </inertial>
   </link>
   <joint type="revolute" name="L_Knee_z">
      <parent link="L_Knee_y_jointbody"/>
      <child link="L_Knee_z_jointbody"/>
      <origin xyz="0.0 0.0 0.0" rpy="0.0 0.0 0.0"/>
      <axis xyz="0.0 0.0 1.0"/>
      <limit lower="-3.141592653589793" upper="3.141592653589793" effort="100" velocity="100"/>
   </joint>
   <joint type="fixed" name="L_Knee_z_offset">
      <parent link="L_Knee_z_jointbody"/>
      <child link="L_Knee"/>
      <origin xyz="-0.0 -0.0 -0.0" rpy="0.0 0.0 0.0"/>
   </joint>
   <link name="L_Ankle">
      <inertial>
         <origin xyz="0.0242 0.0233 -0.0239" rpy="0.0 0.0 0.0"/>
         <mass value="1.5239616"/>
         <inertia ixx="0.0022787543811199997" iyy="0.004763883642112001" izz="0.0048552857790080005" ixy="0" ixz="0" iyz="0"/>
      </inertial>
      <visual>
        <origin xyz="0.0242 0.0233 -0.0239" rpy="0 0 0"/>
        <geometry>
          <box size="0.17 0.0966 0.0928"/>
        </geometry>
      </visual>
      <collision>
        <origin xyz="0.0242 0.0233 -0.0239" rpy="0 0 0"/>
        <geometry>
          <box size="0.17 0.0966 0.0928"/>
        </geometry>
      </collision>
   </link>
   <link name="L_Ankle_x_jointbody">
      <inertial>
         <origin xyz="0.0 0.0 0.0" rpy="0.0 0.0 0.0"/>
         <mass value="0.001"/>
         <inertia ixx="1e-09" iyy="1e-09" izz="1e-09" ixy="0" ixz="0" iyz="0"/>
      </inertial>
   </link>
   <joint type="revolute" name="L_Ankle_x">
      <parent link="L_Knee"/>
      <child link="L_Ankle_x_jointbody"/>
      <origin xyz="-0.0437 -0.0136 -0.398" rpy="0.0 0.0 0.0"/>
      <axis xyz="1.0 0.0 0.0"/>
      <limit lower="-3.141592653589793" upper="3.141592653589793" effort="100" velocity="100"/>
   </joint>
   <link name="L_Ankle_y_jointbody">
      <inertial>
         <origin xyz="0.0 0.0 0.0" rpy="0.0 0.0 0.0"/>
         <mass value="0.001"/>
         <inertia ixx="1e-09" iyy="1e-09" izz="1e-09" ixy="0" ixz="0" iyz="0"/>
      </inertial>
   </link>
   <joint type="revolute" name="L_Ankle_y">
      <parent link="L_Ankle_x_jointbody"/>
      <child link="L_Ankle_y_jointbody"/>
      <origin xyz="0.0 0.0 0.0" rpy="0.0 0.0 0.0"/>
      <axis xyz="0.0 1.0 0.0"/>
      <limit lower="-3.141592653589793" upper="3.141592653589793" effort="100" velocity="100"/>
   </joint>
   <link name="L_Ankle_z_jointbody">
      <inertial>
         <origin xyz="0.0 0.0 0.0" rpy="0.0 0.0 0.0"/>
         <mass value="0.001"/>
         <inertia ixx="1e-09" iyy="1e-09" izz="1e-09" ixy="0" ixz="0" iyz="0"/>
      </inertial>
   </link>
   <joint type="revolute" name="L_Ankle_z">
      <parent link="L_Ankle_y_jointbody"/>
      <child link="L_Ankle_z_jointbody"/>
      <origin xyz="0.0 0.0 0.0" rpy="0.0 0.0 0.0"/>
      <axis xyz="0.0 0.0 1.0"/>
      <limit lower="-3.141592653589793" upper="3.141592653589793" effort="100" velocity="100"/>
   </joint>
   <joint type="fixed" name="L_Ankle_z_offset">
      <parent link="L_Ankle_z_jointbody"/>
      <child link="L_Ankle"/>
      <origin xyz="-0.0 -0.0 -0.0" rpy="0.0 0.0 0.0"/>
   </joint>
   <link name="L_Toe">
      <inertial>
         <origin xyz="0.0248 -0.003 0.0055" rpy="0.0 0.0 0.0"/>
         <mass value="0.37934080000000003"/>
         <inertia ixx="0.00033948978449066677" iyy="0.0003616584608426667" izz="0.0005999906986666667" ixy="0" ixz="0" iyz="0"/>
      </inertial>
   </link>
   <link name="L_Toe_x_jointbody">
      <inertial>
         <origin xyz="0.0 0.0 0.0" rpy="0.0 0.0 0.0"/>
         <mass value="0.001"/>
         <inertia ixx="1e-09" iyy="1e-09" izz="1e-09" ixy="0" ixz="0" iyz="0"/>
      </inertial>
   </link>
   <joint type="revolute" name="L_Toe_x">
      <parent link="L_Ankle"/>
      <child link="L_Toe_x_jointbody"/>
      <origin xyz="0.1193 0.0264 -0.0558" rpy="0.0 0.0 0.0"/>
      <axis xyz="1.0 0.0 0.0"/>
      <limit lower="-3.141592653589793" upper="3.141592653589793" effort="100" velocity="100"/>
   </joint>
   <link name="L_Toe_y_jointbody">
      <inertial>
         <origin xyz="0.0 0.0 0.0" rpy="0.0 0.0 0.0"/>
         <mass value="0.001"/>
         <inertia ixx="1e-09" iyy="1e-09" izz="1e-09" ixy="0" ixz="0" iyz="0"/>
      </inertial>
   </link>
   <joint type="revolute" name="L_Toe_y">
      <parent link="L_Toe_x_jointbody"/>
      <child link="L_Toe_y_jointbody"/>
      <origin xyz="0.0 0.0 0.0" rpy="0.0 0.0 0.0"/>
      <axis xyz="0.0 1.0 0.0"/>
      <limit lower="-3.141592653589793" upper="3.141592653589793" effort="100" velocity="100"/>
   </joint>
   <link name="L_Toe_z_jointbody">
      <inertial>
         <origin xyz="0.0 0.0 0.0" rpy="0.0 0.0 0.0"/>
         <mass value="0.001"/>
         <inertia ixx="1e-09" iyy="1e-09" izz="1e-09" ixy="0" ixz="0" iyz="0"/>
      </inertial>
   </link>
   <joint type="revolute" name="L_Toe_z">
      <parent link="L_Toe_y_jointbody"/>
      <child link="L_Toe_z_jointbody"/>
      <origin xyz="0.0 0.0 0.0" rpy="0.0 0.0 0.0"/>
      <axis xyz="0.0 0.0 1.0"/>
      <limit lower="-3.141592653589793" upper="3.141592653589793" effort="100" velocity="100"/>
   </joint>
   <joint type="fixed" name="L_Toe_z_offset">
      <parent link="L_Toe_z_jointbody"/>
      <child link="L_Toe"/>
      <origin xyz="-0.0 -0.0 -0.0" rpy="0.0 0.0 0.0"/>
   </joint>
   <link name="R_Hip">
      <inertial>
         <origin xyz="-0.00445 -0.01915 -0.1913" rpy="-0.099409909127235 0.02296561924175622 -0.001142496142428076"/>
         <mass value="7.3366288705909914"/>
         <inertia ixx="0.06721955301107428" iyy="0.06721955301107428" izz="0.012772727655586845" ixy="0" ixz="0" iyz="0"/>
      </inertial>
   </link>
   <link name="R_Hip_x_jointbody">
      <inertial>
         <origin xyz="0.0 0.0 0.0" rpy="0.0 0.0 0.0"/>
         <mass value="0.001"/>
         <inertia ixx="1e-09" iyy="1e-09" izz="1e-09" ixy="0" ixz="0" iyz="0"/>
      </inertial>
   </link>
   <joint type="revolute" name="R_Hip_x">
      <parent link="Pelvis"/>
      <child link="R_Hip_x_jointbody"/>
      <origin xyz="-0.0043 -0.0677 -0.0905" rpy="0.0 0.0 0.0"/>
      <axis xyz="1.0 0.0 0.0"/>
      <limit lower="-3.141592653589793" upper="3.141592653589793" effort="100" velocity="100"/>
   </joint>
   <link name="R_Hip_y_jointbody">
      <inertial>
         <origin xyz="0.0 0.0 0.0" rpy="0.0 0.0 0.0"/>
         <mass value="0.001"/>
         <inertia ixx="1e-09" iyy="1e-09" izz="1e-09" ixy="0" ixz="0" iyz="0"/>
      </inertial>
   </link>
   <joint type="revolute" name="R_Hip_y">
      <parent link="R_Hip_x_jointbody"/>
      <child link="R_Hip_y_jointbody"/>
      <origin xyz="0.0 0.0 0.0" rpy="0.0 0.0 0.0"/>
      <axis xyz="0.0 1.0 0.0"/>
      <limit lower="-3.141592653589793" upper="3.141592653589793" effort="100" velocity="100"/>
   </joint>
   <link name="R_Hip_z_jointbody">
      <inertial>
         <origin xyz="0.0 0.0 0.0" rpy="0.0 0.0 0.0"/>
         <mass value="0.001"/>
         <inertia ixx="1e-09" iyy="1e-09" izz="1e-09" ixy="0" ixz="0" iyz="0"/>
      </inertial>
   </link>
   <joint type="revolute" name="R_Hip_z">
      <parent link="R_Hip_y_jointbody"/>
      <child link="R_Hip_z_jointbody"/>
      <origin xyz="0.0 0.0 0.0" rpy="0.0 0.0 0.0"/>
      <axis xyz="0.0 0.0 1.0"/>
      <limit lower="-3.141592653589793" upper="3.141592653589793" effort="100" velocity="100"/>
   </joint>
   <joint type="fixed" name="R_Hip_z_offset">
      <parent link="R_Hip_z_jointbody"/>
      <child link="R_Hip"/>
      <origin xyz="-0.0 -0.0 -0.0" rpy="0.0 0.0 0.0"/>
   </joint>
   <link name="R_Knee">
      <inertial>
         <origin xyz="-0.02115 0.0079 -0.1992" rpy="0.0393102827044153 0.10538409418780237 0.0020735246720312503"/>
         <mass value="3.5491244915639744"/>
         <inertia ixx="0.031956326333558646" iyy="0.031956326333558646" izz="0.00495414963842792" ixy="0" ixz="0" iyz="0"/>
      </inertial>
   </link>
   <link name="R_Knee_x_jointbody">
      <inertial>
         <origin xyz="0.0 0.0 0.0" rpy="0.0 0.0 0.0"/>
         <mass value="0.001"/>
         <inertia ixx="1e-09" iyy="1e-09" izz="1e-09" ixy="0" ixz="0" iyz="0"/>
      </inertial>
   </link>
   <joint type="revolute" name="R_Knee_x">
      <parent link="R_Hip"/>
      <child link="R_Knee_x_jointbody"/>
      <origin xyz="-0.0089 -0.0383 -0.3826" rpy="0.0 0.0 0.0"/>
      <axis xyz="1.0 0.0 0.0"/>
      <limit lower="-3.141592653589793" upper="3.141592653589793" effort="100" velocity="100"/>
   </joint>
   <link name="R_Knee_y_jointbody">
      <inertial>
         <origin xyz="0.0 0.0 0.0" rpy="0.0 0.0 0.0"/>
         <mass value="0.001"/>
         <inertia ixx="1e-09" iyy="1e-09" izz="1e-09" ixy="0" ixz="0" iyz="0"/>
      </inertial>
   </link>
   <joint type="revolute" name="R_Knee_y">
      <parent link="R_Knee_x_jointbody"/>
      <child link="R_Knee_y_jointbody"/>
      <origin xyz="0.0 0.0 0.0" rpy="0.0 0.0 0.0"/>
      <axis xyz="0.0 1.0 0.0"/>
      <limit lower="-3.141592653589793" upper="3.141592653589793" effort="100" velocity="100"/>
   </joint>
   <link name="R_Knee_z_jointbody">
      <inertial>
         <origin xyz="0.0 0.0 0.0" rpy="0.0 0.0 0.0"/>
         <mass value="0.001"/>
         <inertia ixx="1e-09" iyy="1e-09" izz="1e-09" ixy="0" ixz="0" iyz="0"/>
      </inertial>
   </link>
   <joint type="revolute" name="R_Knee_z">
      <parent link="R_Knee_y_jointbody"/>
      <child link="R_Knee_z_jointbody"/>
      <origin xyz="0.0 0.0 0.0" rpy="0.0 0.0 0.0"/>
      <axis xyz="0.0 0.0 1.0"/>
      <limit lower="-3.141592653589793" upper="3.141592653589793" effort="100" velocity="100"/>
   </joint>
   <joint type="fixed" name="R_Knee_z_offset">
      <parent link="R_Knee_z_jointbody"/>
      <child link="R_Knee"/>
      <origin xyz="-0.0 -0.0 -0.0" rpy="0.0 0.0 0.0"/>
   </joint>
   <link name="R_Ankle">
      <inertial>
         <origin xyz="0.0256 -0.0212 -0.0174" rpy="0.0 0.0 0.0"/>
         <mass value="1.59764808"/>
         <inertia ixx="0.0024591691561528" iyy="0.005201457528562399" izz="0.005227046525310399" ixy="0" ixz="0" iyz="0"/>
      </inertial>
   </link>
   <link name="R_Ankle_x_jointbody">
      <inertial>
         <origin xyz="0.0 0.0 0.0" rpy="0.0 0.0 0.0"/>
         <mass value="0.001"/>
         <inertia ixx="1e-09" iyy="1e-09" izz="1e-09" ixy="0" ixz="0" iyz="0"/>
      </inertial>
   </link>
   <joint type="revolute" name="R_Ankle_x">
      <parent link="R_Knee"/>
      <child link="R_Ankle_x_jointbody"/>
      <origin xyz="-0.0423 0.0158 -0.3984" rpy="0.0 0.0 0.0"/>
      <axis xyz="1.0 0.0 0.0"/>
      <limit lower="-3.141592653589793" upper="3.141592653589793" effort="100" velocity="100"/>
   </joint>
   <link name="R_Ankle_y_jointbody">
      <inertial>
         <origin xyz="0.0 0.0 0.0" rpy="0.0 0.0 0.0"/>
         <mass value="0.001"/>
         <inertia ixx="1e-09" iyy="1e-09" izz="1e-09" ixy="0" ixz="0" iyz="0"/>
      </inertial>
   </link>
   <joint type="revolute" name="R_Ankle_y">
      <parent link="R_Ankle_x_jointbody"/>
      <child link="R_Ankle_y_jointbody"/>
      <origin xyz="0.0 0.0 0.0" rpy="0.0 0.0 0.0"/>
      <axis xyz="0.0 1.0 0.0"/>
      <limit lower="-3.141592653589793" upper="3.141592653589793" effort="100" velocity="100"/>
   </joint>
   <link name="R_Ankle_z_jointbody">
      <inertial>
         <origin xyz="0.0 0.0 0.0" rpy="0.0 0.0 0.0"/>
         <mass value="0.001"/>
         <inertia ixx="1e-09" iyy="1e-09" izz="1e-09" ixy="0" ixz="0" iyz="0"/>
      </inertial>
   </link>
   <joint type="revolute" name="R_Ankle_z">
      <parent link="R_Ankle_y_jointbody"/>
      <child link="R_Ankle_z_jointbody"/>
      <origin xyz="0.0 0.0 0.0" rpy="0.0 0.0 0.0"/>
      <axis xyz="0.0 0.0 1.0"/>
      <limit lower="-3.141592653589793" upper="3.141592653589793" effort="100" velocity="100"/>
   </joint>
   <joint type="fixed" name="R_Ankle_z_offset">
      <parent link="R_Ankle_z_jointbody"/>
      <child link="R_Ankle"/>
      <origin xyz="-0.0 -0.0 -0.0" rpy="0.0 0.0 0.0"/>
   </joint>
   <link name="R_Toe">
      <inertial>
         <origin xyz="0.0227 0.0042 0.0045" rpy="0.0 0.0 0.0"/>
         <mass value="0.4080620159999999"/>
         <inertia ixx="0.0003755489947718399" iyy="0.00039405868781759983" izz="0.0006426840731327998" ixy="0" ixz="0" iyz="0"/>
      </inertial>
   </link>
   <link name="R_Toe_x_jointbody">
      <inertial>
         <origin xyz="0.0 0.0 0.0" rpy="0.0 0.0 0.0"/>
         <mass value="0.001"/>
         <inertia ixx="1e-09" iyy="1e-09" izz="1e-09" ixy="0" ixz="0" iyz="0"/>
      </inertial>
   </link>
   <joint type="revolute" name="R_Toe_x">
      <parent link="R_Ankle"/>
      <child link="R_Toe_x_jointbody"/>
      <origin xyz="0.1233 -0.0254 -0.0481" rpy="0.0 0.0 0.0"/>
      <axis xyz="1.0 0.0 0.0"/>
      <limit lower="-3.141592653589793" upper="3.141592653589793" effort="100" velocity="100"/>
   </joint>
   <link name="R_Toe_y_jointbody">
      <inertial>
         <origin xyz="0.0 0.0 0.0" rpy="0.0 0.0 0.0"/>
         <mass value="0.001"/>
         <inertia ixx="1e-09" iyy="1e-09" izz="1e-09" ixy="0" ixz="0" iyz="0"/>
      </inertial>
   </link>
   <joint type="revolute" name="R_Toe_y">
      <parent link="R_Toe_x_jointbody"/>
      <child link="R_Toe_y_jointbody"/>
      <origin xyz="0.0 0.0 0.0" rpy="0.0 0.0 0.0"/>
      <axis xyz="0.0 1.0 0.0"/>
      <limit lower="-3.141592653589793" upper="3.141592653589793" effort="100" velocity="100"/>
   </joint>
   <link name="R_Toe_z_jointbody">
      <inertial>
         <origin xyz="0.0 0.0 0.0" rpy="0.0 0.0 0.0"/>
         <mass value="0.001"/>
         <inertia ixx="1e-09" iyy="1e-09" izz="1e-09" ixy="0" ixz="0" iyz="0"/>
      </inertial>
   </link>
   <joint type="revolute" name="R_Toe_z">
      <parent link="R_Toe_y_jointbody"/>
      <child link="R_Toe_z_jointbody"/>
      <origin xyz="0.0 0.0 0.0" rpy="0.0 0.0 0.0"/>
      <axis xyz="0.0 0.0 1.0"/>
      <limit lower="-3.141592653589793" upper="3.141592653589793" effort="100" velocity="100"/>
   </joint>
   <joint type="fixed" name="R_Toe_z_offset">
      <parent link="R_Toe_z_jointbody"/>
      <child link="R_Toe"/>
      <origin xyz="-0.0 -0.0 -0.0" rpy="0.0 0.0 0.0"/>
   </joint>
   <link name="Torso">
      <inertial>
         <origin xyz="0.0005499999999999999 0.00275 0.06755" rpy="3.104572537715863 -0.007402196904007896 -0.39465408833044546"/>
         <mass value="4.399722331022851"/>
         <inertia ixx="0.011652622321689485" iyy="0.011652622321689485" izz="0.010710199029244805" ixy="0" ixz="0" iyz="0"/>
      </inertial>
   </link>
   <link name="Torso_x_jointbody">
      <inertial>
         <origin xyz="0.0 0.0 0.0" rpy="0.0 0.0 0.0"/>
         <mass value="0.001"/>
         <inertia ixx="1e-09" iyy="1e-09" izz="1e-09" ixy="0" ixz="0" iyz="0"/>
      </inertial>
   </link>
   <joint type="revolute" name="Torso_x">
      <parent link="Pelvis"/>
      <child link="Torso_x_jointbody"/>
      <origin xyz="-0.0267 -0.0025 0.109" rpy="0.0 0.0 0.0"/>
      <axis xyz="1.0 0.0 0.0"/>
      <limit lower="-3.141592653589793" upper="3.141592653589793" effort="100" velocity="100"/>
   </joint>
   <link name="Torso_y_jointbody">
      <inertial>
         <origin xyz="0.0 0.0 0.0" rpy="0.0 0.0 0.0"/>
         <mass value="0.001"/>
         <inertia ixx="1e-09" iyy="1e-09" izz="1e-09" ixy="0" ixz="0" iyz="0"/>
      </inertial>
   </link>
   <joint type="revolute" name="Torso_y">
      <parent link="Torso_x_jointbody"/>
      <child link="Torso_y_jointbody"/>
      <origin xyz="0.0 0.0 0.0" rpy="0.0 0.0 0.0"/>
      <axis xyz="0.0 1.0 0.0"/>
      <limit lower="-3.141592653589793" upper="3.141592653589793" effort="100" velocity="100"/>
   </joint>
   <link name="Torso_z_jointbody">
      <inertial>
         <origin xyz="0.0 0.0 0.0" rpy="0.0 0.0 0.0"/>
         <mass value="0.001"/>
         <inertia ixx="1e-09" iyy="1e-09" izz="1e-09" ixy="0" ixz="0" iyz="0"/>
      </inertial>
   </link>
   <joint type="revolute" name="Torso_z">
      <parent link="Torso_y_jointbody"/>
      <child link="Torso_z_jointbody"/>
      <origin xyz="0.0 0.0 0.0" rpy="0.0 0.0 0.0"/>
      <axis xyz="0.0 0.0 1.0"/>
      <limit lower="-3.141592653589793" upper="3.141592653589793" effort="100" velocity="100"/>
   </joint>
   <joint type="fixed" name="Torso_z_offset">
      <parent link="Torso_z_jointbody"/>
      <child link="Torso"/>
      <origin xyz="-0.0 -0.0 -0.0" rpy="0.0 0.0 0.0"/>
   </joint>
   <link name="Spine">
      <inertial>
         <origin xyz="0.0127 0.00075 0.02645" rpy="3.122726967568122 -0.45600163020547724 -3.0603298406827135"/>
         <mass value="3.894810564943408"/>
         <inertia ixx="0.009343747338491437" iyy="0.009343747338491437" izz="0.009003557619888589" ixy="0" ixz="0" iyz="0"/>
      </inertial>
   </link>
   <link name="Spine_x_jointbody">
      <inertial>
         <origin xyz="0.0 0.0 0.0" rpy="0.0 0.0 0.0"/>
         <mass value="0.001"/>
         <inertia ixx="1e-09" iyy="1e-09" izz="1e-09" ixy="0" ixz="0" iyz="0"/>
      </inertial>
   </link>
   <joint type="revolute" name="Spine_x">
      <parent link="Torso"/>
      <child link="Spine_x_jointbody"/>
      <origin xyz="0.0011 0.0055 0.1352" rpy="0.0 0.0 0.0"/>
      <axis xyz="1.0 0.0 0.0"/>
      <limit lower="-3.141592653589793" upper="3.141592653589793" effort="100" velocity="100"/>
   </joint>
   <link name="Spine_y_jointbody">
      <inertial>
         <origin xyz="0.0 0.0 0.0" rpy="0.0 0.0 0.0"/>
         <mass value="0.001"/>
         <inertia ixx="1e-09" iyy="1e-09" izz="1e-09" ixy="0" ixz="0" iyz="0"/>
      </inertial>
   </link>
   <joint type="revolute" name="Spine_y">
      <parent link="Spine_x_jointbody"/>
      <child link="Spine_y_jointbody"/>
      <origin xyz="0.0 0.0 0.0" rpy="0.0 0.0 0.0"/>
      <axis xyz="0.0 1.0 0.0"/>
      <limit lower="-3.141592653589793" upper="3.141592653589793" effort="100" velocity="100"/>
   </joint>
   <link name="Spine_z_jointbody">
      <inertial>
         <origin xyz="0.0 0.0 0.0" rpy="0.0 0.0 0.0"/>
         <mass value="0.001"/>
         <inertia ixx="1e-09" iyy="1e-09" izz="1e-09" ixy="0" ixz="0" iyz="0"/>
      </inertial>
   </link>
   <joint type="revolute" name="Spine_z">
      <parent link="Spine_y_jointbody"/>
      <child link="Spine_z_jointbody"/>
      <origin xyz="0.0 0.0 0.0" rpy="0.0 0.0 0.0"/>
      <axis xyz="0.0 0.0 1.0"/>
      <limit lower="-3.141592653589793" upper="3.141592653589793" effort="100" velocity="100"/>
   </joint>
   <joint type="fixed" name="Spine_z_offset">
      <parent link="Spine_z_jointbody"/>
      <child link="Spine"/>
      <origin xyz="-0.0 -0.0 -0.0" rpy="0.0 0.0 0.0"/>
   </joint>
   <link name="Chest">
      <inertial>
         <origin xyz="-0.01925 -0.00095 0.07575" rpy="-3.1349702338471253 0.2527492467771628 -3.0894804437929406"/>
         <mass value="9.603862393566706"/>
         <inertia ixx="0.04264033314552843" iyy="0.04264033314552843" izz="0.039577201711618056" ixy="0" ixz="0" iyz="0"/>
      </inertial>
   </link>
   <link name="Chest_x_jointbody">
      <inertial>
         <origin xyz="0.0 0.0 0.0" rpy="0.0 0.0 0.0"/>
         <mass value="0.001"/>
         <inertia ixx="1e-09" iyy="1e-09" izz="1e-09" ixy="0" ixz="0" iyz="0"/>
      </inertial>
   </link>
   <joint type="revolute" name="Chest_x">
      <parent link="Spine"/>
      <child link="Chest_x_jointbody"/>
      <origin xyz="0.0254 0.0015 0.0529" rpy="0.0 0.0 0.0"/>
      <axis xyz="1.0 0.0 0.0"/>
      <limit lower="-3.141592653589793" upper="3.141592653589793" effort="100" velocity="100"/>
   </joint>
   <link name="Chest_y_jointbody">
      <inertial>
         <origin xyz="0.0 0.0 0.0" rpy="0.0 0.0 0.0"/>
         <mass value="0.001"/>
         <inertia ixx="1e-09" iyy="1e-09" izz="1e-09" ixy="0" ixz="0" iyz="0"/>
      </inertial>
   </link>
   <joint type="revolute" name="Chest_y">
      <parent link="Chest_x_jointbody"/>
      <child link="Chest_y_jointbody"/>
      <origin xyz="0.0 0.0 0.0" rpy="0.0 0.0 0.0"/>
      <axis xyz="0.0 1.0 0.0"/>
      <limit lower="-3.141592653589793" upper="3.141592653589793" effort="100" velocity="100"/>
   </joint>
   <link name="Chest_z_jointbody">
      <inertial>
         <origin xyz="0.0 0.0 0.0" rpy="0.0 0.0 0.0"/>
         <mass value="0.001"/>
         <inertia ixx="1e-09" iyy="1e-09" izz="1e-09" ixy="0" ixz="0" iyz="0"/>
      </inertial>
   </link>
   <joint type="revolute" name="Chest_z">
      <parent link="Chest_y_jointbody"/>
      <child link="Chest_z_jointbody"/>
      <origin xyz="0.0 0.0 0.0" rpy="0.0 0.0 0.0"/>
      <axis xyz="0.0 0.0 1.0"/>
      <limit lower="-3.141592653589793" upper="3.141592653589793" effort="100" velocity="100"/>
   </joint>
   <joint type="fixed" name="Chest_z_offset">
      <parent link="Chest_z_jointbody"/>
      <child link="Chest"/>
      <origin xyz="-0.0 -0.0 -0.0" rpy="0.0 0.0 0.0"/>
   </joint>
   <link name="Neck">
      <inertial>
         <origin xyz="0.0257 0.00255 0.0325" rpy="3.0622722479394406 -0.6669245178418417 -2.9134804794662346"/>
         <mass value="0.6445350243327338"/>
         <inertia ixx="0.0009645577477889074" iyy="0.0009645577477889074" izz="0.0005466211269081562" ixy="0" ixz="0" iyz="0"/>
      </inertial>
   </link>
   <link name="Neck_x_jointbody">
      <inertial>
         <origin xyz="0.0 0.0 0.0" rpy="0.0 0.0 0.0"/>
         <mass value="0.001"/>
         <inertia ixx="1e-09" iyy="1e-09" izz="1e-09" ixy="0" ixz="0" iyz="0"/>
      </inertial>
   </link>
   <joint type="revolute" name="Neck_x">
      <parent link="Chest"/>
      <child link="Neck_x_jointbody"/>
      <origin xyz="-0.0429 -0.0028 0.2139" rpy="0.0 0.0 0.0"/>
      <axis xyz="1.0 0.0 0.0"/>
      <limit lower="-3.141592653589793" upper="3.141592653589793" effort="100" velocity="100"/>
   </joint>
   <link name="Neck_y_jointbody">
      <inertial>
         <origin xyz="0.0 0.0 0.0" rpy="0.0 0.0 0.0"/>
         <mass value="0.001"/>
         <inertia ixx="1e-09" iyy="1e-09" izz="1e-09" ixy="0" ixz="0" iyz="0"/>
      </inertial>
   </link>
   <joint type="revolute" name="Neck_y">
      <parent link="Neck_x_jointbody"/>
      <child link="Neck_y_jointbody"/>
      <origin xyz="0.0 0.0 0.0" rpy="0.0 0.0 0.0"/>
      <axis xyz="0.0 1.0 0.0"/>
      <limit lower="-3.141592653589793" upper="3.141592653589793" effort="100" velocity="100"/>
   </joint>
   <link name="Neck_z_jointbody">
      <inertial>
         <origin xyz="0.0 0.0 0.0" rpy="0.0 0.0 0.0"/>
         <mass value="0.001"/>
         <inertia ixx="1e-09" iyy="1e-09" izz="1e-09" ixy="0" ixz="0" iyz="0"/>
      </inertial>
   </link>
   <joint type="revolute" name="Neck_z">
      <parent link="Neck_y_jointbody"/>
      <child link="Neck_z_jointbody"/>
      <origin xyz="0.0 0.0 0.0" rpy="0.0 0.0 0.0"/>
      <axis xyz="0.0 0.0 1.0"/>
      <limit lower="-3.141592653589793" upper="3.141592653589793" effort="100" velocity="100"/>
   </joint>
   <joint type="fixed" name="Neck_z_offset">
      <parent link="Neck_z_jointbody"/>
      <child link="Neck"/>
      <origin xyz="-0.0 -0.0 -0.0" rpy="0.0 0.0 0.0"/>
   </joint>
   <link name="Head">
      <inertial>
         <origin xyz="-0.0116 -0.0042 0.0876" rpy="0.0 0.0 0.0"/>
         <mass value="4.25188992"/>
         <inertia ixx="0.024079189611212803" iyy="0.0270606715149824" izz="0.0133911288815104" ixy="0" ixz="0" iyz="0"/>
      </inertial>
   </link>
   <link name="Head_x_jointbody">
      <inertial>
         <origin xyz="0.0 0.0 0.0" rpy="0.0 0.0 0.0"/>
         <mass value="0.001"/>
         <inertia ixx="1e-09" iyy="1e-09" izz="1e-09" ixy="0" ixz="0" iyz="0"/>
      </inertial>
   </link>
   <joint type="revolute" name="Head_x">
      <parent link="Neck"/>
      <child link="Head_x_jointbody"/>
      <origin xyz="0.0513 0.0052 0.065" rpy="0.0 0.0 0.0"/>
      <axis xyz="1.0 0.0 0.0"/>
      <limit lower="-3.141592653589793" upper="3.141592653589793" effort="100" velocity="100"/>
   </joint>
   <link name="Head_y_jointbody">
      <inertial>
         <origin xyz="0.0 0.0 0.0" rpy="0.0 0.0 0.0"/>
         <mass value="0.001"/>
         <inertia ixx="1e-09" iyy="1e-09" izz="1e-09" ixy="0" ixz="0" iyz="0"/>
      </inertial>
   </link>
   <joint type="revolute" name="Head_y">
      <parent link="Head_x_jointbody"/>
      <child link="Head_y_jointbody"/>
      <origin xyz="0.0 0.0 0.0" rpy="0.0 0.0 0.0"/>
      <axis xyz="0.0 1.0 0.0"/>
      <limit lower="-3.141592653589793" upper="3.141592653589793" effort="100" velocity="100"/>
   </joint>
   <link name="Head_z_jointbody">
      <inertial>
         <origin xyz="0.0 0.0 0.0" rpy="0.0 0.0 0.0"/>
         <mass value="0.001"/>
         <inertia ixx="1e-09" iyy="1e-09" izz="1e-09" ixy="0" ixz="0" iyz="0"/>
      </inertial>
   </link>
   <joint type="revolute" name="Head_z">
      <parent link="Head_y_jointbody"/>
      <child link="Head_z_jointbody"/>
      <origin xyz="0.0 0.0 0.0" rpy="0.0 0.0 0.0"/>
      <axis xyz="0.0 0.0 1.0"/>
      <limit lower="-3.141592653589793" upper="3.141592653589793" effort="100" velocity="100"/>
   </joint>
   <joint type="fixed" name="Head_z_offset">
      <parent link="Head_z_jointbody"/>
      <child link="Head"/>
      <origin xyz="-0.0 -0.0 -0.0" rpy="0.0 0.0 0.0"/>
   </joint>
   <link name="L_Thorax">
      <inertial>
         <origin xyz="-0.00445 0.0455 0.015250000000000001" rpy="1.8941943261590979 0.09177904219412159 0.12747471353551298"/>
         <mass value="1.0855188482089504"/>
         <inertia ixx="0.0022797974241773747" iyy="0.0022797974241773747" izz="0.0013124748734916268" ixy="0" ixz="0" iyz="0"/>
      </inertial>
   </link>
   <link name="L_Thorax_x_jointbody">
      <inertial>
         <origin xyz="0.0 0.0 0.0" rpy="0.0 0.0 0.0"/>
         <mass value="0.001"/>
         <inertia ixx="1e-09" iyy="1e-09" izz="1e-09" ixy="0" ixz="0" iyz="0"/>
      </inertial>
   </link>
   <joint type="revolute" name="L_Thorax_x">
      <parent link="Chest"/>
      <child link="L_Thorax_x_jointbody"/>
      <origin xyz="-0.0341 0.0788 0.1217" rpy="0.0 0.0 0.0"/>
      <axis xyz="1.0 0.0 0.0"/>
      <limit lower="-3.141592653589793" upper="3.141592653589793" effort="100" velocity="100"/>
   </joint>
   <link name="L_Thorax_y_jointbody">
      <inertial>
         <origin xyz="0.0 0.0 0.0" rpy="0.0 0.0 0.0"/>
         <mass value="0.001"/>
         <inertia ixx="1e-09" iyy="1e-09" izz="1e-09" ixy="0" ixz="0" iyz="0"/>
      </inertial>
   </link>
   <joint type="revolute" name="L_Thorax_y">
      <parent link="L_Thorax_x_jointbody"/>
      <child link="L_Thorax_y_jointbody"/>
      <origin xyz="0.0 0.0 0.0" rpy="0.0 0.0 0.0"/>
      <axis xyz="0.0 1.0 0.0"/>
      <limit lower="-3.141592653589793" upper="3.141592653589793" effort="100" velocity="100"/>
   </joint>
   <link name="L_Thorax_z_jointbody">
      <inertial>
         <origin xyz="0.0 0.0 0.0" rpy="0.0 0.0 0.0"/>
         <mass value="0.001"/>
         <inertia ixx="1e-09" iyy="1e-09" izz="1e-09" ixy="0" ixz="0" iyz="0"/>
      </inertial>
   </link>
   <joint type="revolute" name="L_Thorax_z">
      <parent link="L_Thorax_y_jointbody"/>
      <child link="L_Thorax_z_jointbody"/>
      <origin xyz="0.0 0.0 0.0" rpy="0.0 0.0 0.0"/>
      <axis xyz="0.0 0.0 1.0"/>
      <limit lower="-3.141592653589793" upper="3.141592653589793" effort="100" velocity="100"/>
   </joint>
   <joint type="fixed" name="L_Thorax_z_offset">
      <parent link="L_Thorax_z_jointbody"/>
      <child link="L_Thorax"/>
      <origin xyz="-0.0 -0.0 -0.0" rpy="0.0 0.0 0.0"/>
   </joint>
   <link name="L_Shoulder">
      <inertial>
         <origin xyz="-0.013749999999999998 0.1298 -0.0064" rpy="1.522054475484965 0.10538732625807135 0.1003804214880526"/>
         <mass value="1.895978601307495"/>
         <inertia ixx="0.00952023134718312" iyy="0.00952023134718312" izz="0.002379152950107374" ixy="0" ixz="0" iyz="0"/>
      </inertial>
   </link>
   <link name="L_Shoulder_x_jointbody">
      <inertial>
         <origin xyz="0.0 0.0 0.0" rpy="0.0 0.0 0.0"/>
         <mass value="0.001"/>
         <inertia ixx="1e-09" iyy="1e-09" izz="1e-09" ixy="0" ixz="0" iyz="0"/>
      </inertial>
   </link>
   <joint type="revolute" name="L_Shoulder_x">
      <parent link="L_Thorax"/>
      <child link="L_Shoulder_x_jointbody"/>
      <origin xyz="-0.0089 0.091 0.0305" rpy="0.0 0.0 0.0"/>
      <axis xyz="1.0 0.0 0.0"/>
      <limit lower="-12.566370614359172" upper="12.566370614359172" effort="100" velocity="100"/>
   </joint>
   <link name="L_Shoulder_y_jointbody">
      <inertial>
         <origin xyz="0.0 0.0 0.0" rpy="0.0 0.0 0.0"/>
         <mass value="0.001"/>
         <inertia ixx="1e-09" iyy="1e-09" izz="1e-09" ixy="0" ixz="0" iyz="0"/>
      </inertial>
   </link>
   <joint type="revolute" name="L_Shoulder_y">
      <parent link="L_Shoulder_x_jointbody"/>
      <child link="L_Shoulder_y_jointbody"/>
      <origin xyz="0.0 0.0 0.0" rpy="0.0 0.0 0.0"/>
      <axis xyz="0.0 1.0 0.0"/>
      <limit lower="-12.566370614359172" upper="12.566370614359172" effort="100" velocity="100"/>
   </joint>
   <link name="L_Shoulder_z_jointbody">
      <inertial>
         <origin xyz="0.0 0.0 0.0" rpy="0.0 0.0 0.0"/>
         <mass value="0.001"/>
         <inertia ixx="1e-09" iyy="1e-09" izz="1e-09" ixy="0" ixz="0" iyz="0"/>
      </inertial>
   </link>
   <joint type="revolute" name="L_Shoulder_z">
      <parent link="L_Shoulder_y_jointbody"/>
      <child link="L_Shoulder_z_jointbody"/>
      <origin xyz="0.0 0.0 0.0" rpy="0.0 0.0 0.0"/>
      <axis xyz="0.0 0.0 1.0"/>
      <limit lower="-12.566370614359172" upper="12.566370614359172" effort="100" velocity="100"/>
   </joint>
   <joint type="fixed" name="L_Shoulder_z_offset">
      <parent link="L_Shoulder_z_jointbody"/>
      <child link="L_Shoulder"/>
      <origin xyz="-0.0 -0.0 -0.0" rpy="0.0 0.0 0.0"/>
   </joint>
   <link name="L_Elbow">
      <inertial>
         <origin xyz="-0.00055 0.12459999999999999 0.0045" rpy="1.606876918641257 0.004676064957103154 0.004847898060720945"/>
         <mass value="1.049660741087868"/>
         <inertia ixx="0.004131056907411824" iyy="0.004131056907411824" izz="0.0008152111142062166" ixy="0" ixz="0" iyz="0"/>
      </inertial>
   </link>
   <link name="L_Elbow_x_jointbody">
      <inertial>
         <origin xyz="0.0 0.0 0.0" rpy="0.0 0.0 0.0"/>
         <mass value="0.001"/>
         <inertia ixx="1e-09" iyy="1e-09" izz="1e-09" ixy="0" ixz="0" iyz="0"/>
      </inertial>
   </link>
   <joint type="revolute" name="L_Elbow_x">
      <parent link="L_Shoulder"/>
      <child link="L_Elbow_x_jointbody"/>
      <origin xyz="-0.0275 0.2596 -0.0128" rpy="0.0 0.0 0.0"/>
      <axis xyz="1.0 0.0 0.0"/>
      <limit lower="-12.566370614359172" upper="12.566370614359172" effort="100" velocity="100"/>
   </joint>
   <link name="L_Elbow_y_jointbody">
      <inertial>
         <origin xyz="0.0 0.0 0.0" rpy="0.0 0.0 0.0"/>
         <mass value="0.001"/>
         <inertia ixx="1e-09" iyy="1e-09" izz="1e-09" ixy="0" ixz="0" iyz="0"/>
      </inertial>
   </link>
   <joint type="revolute" name="L_Elbow_y">
      <parent link="L_Elbow_x_jointbody"/>
      <child link="L_Elbow_y_jointbody"/>
      <origin xyz="0.0 0.0 0.0" rpy="0.0 0.0 0.0"/>
      <axis xyz="0.0 1.0 0.0"/>
      <limit lower="-12.566370614359172" upper="12.566370614359172" effort="100" velocity="100"/>
   </joint>
   <link name="L_Elbow_z_jointbody">
      <inertial>
         <origin xyz="0.0 0.0 0.0" rpy="0.0 0.0 0.0"/>
         <mass value="0.001"/>
         <inertia ixx="1e-09" iyy="1e-09" izz="1e-09" ixy="0" ixz="0" iyz="0"/>
      </inertial>
   </link>
   <joint type="revolute" name="L_Elbow_z">
      <parent link="L_Elbow_y_jointbody"/>
      <child link="L_Elbow_z_jointbody"/>
      <origin xyz="0.0 0.0 0.0" rpy="0.0 0.0 0.0"/>
      <axis xyz="0.0 0.0 1.0"/>
      <limit lower="-12.566370614359172" upper="12.566370614359172" effort="100" velocity="100"/>
   </joint>
   <joint type="fixed" name="L_Elbow_z_offset">
      <parent link="L_Elbow_z_jointbody"/>
      <child link="L_Elbow"/>
      <origin xyz="-0.0 -0.0 -0.0" rpy="0.0 0.0 0.0"/>
   </joint>
   <link name="L_Wrist">
      <inertial>
         <origin xyz="-0.0075 0.041999999999999996 -0.00405" rpy="1.4738786990005337 0.1758966280112524 0.1596974832404865"/>
         <mass value="0.29809278062183087"/>
         <inertia ixx="0.0003035005683439096" iyy="0.0003035005683439096" izz="0.0001371001944932836" ixy="0" ixz="0" iyz="0"/>
      </inertial>
   </link>
   <link name="L_Wrist_x_jointbody">
      <inertial>
         <origin xyz="0.0 0.0 0.0" rpy="0.0 0.0 0.0"/>
         <mass value="0.001"/>
         <inertia ixx="1e-09" iyy="1e-09" izz="1e-09" ixy="0" ixz="0" iyz="0"/>
      </inertial>
   </link>
   <joint type="revolute" name="L_Wrist_x">
      <parent link="L_Elbow"/>
      <child link="L_Wrist_x_jointbody"/>
      <origin xyz="-0.0012 0.2492 0.009" rpy="0.0 0.0 0.0"/>
      <axis xyz="1.0 0.0 0.0"/>
      <limit lower="-3.141592653589793" upper="3.141592653589793" effort="100" velocity="100"/>
   </joint>
   <link name="L_Wrist_y_jointbody">
      <inertial>
         <origin xyz="0.0 0.0 0.0" rpy="0.0 0.0 0.0"/>
         <mass value="0.001"/>
         <inertia ixx="1e-09" iyy="1e-09" izz="1e-09" ixy="0" ixz="0" iyz="0"/>
      </inertial>
   </link>
   <joint type="revolute" name="L_Wrist_y">
      <parent link="L_Wrist_x_jointbody"/>
      <child link="L_Wrist_y_jointbody"/>
      <origin xyz="0.0 0.0 0.0" rpy="0.0 0.0 0.0"/>
      <axis xyz="0.0 1.0 0.0"/>
      <limit lower="-3.141592653589793" upper="3.141592653589793" effort="100" velocity="100"/>
   </joint>
   <link name="L_Wrist_z_jointbody">
      <inertial>
         <origin xyz="0.0 0.0 0.0" rpy="0.0 0.0 0.0"/>
         <mass value="0.001"/>
         <inertia ixx="1e-09" iyy="1e-09" izz="1e-09" ixy="0" ixz="0" iyz="0"/>
      </inertial>
   </link>
   <joint type="revolute" name="L_Wrist_z">
      <parent link="L_Wrist_y_jointbody"/>
      <child link="L_Wrist_z_jointbody"/>
      <origin xyz="0.0 0.0 0.0" rpy="0.0 0.0 0.0"/>
      <axis xyz="0.0 0.0 1.0"/>
      <limit lower="-3.141592653589793" upper="3.141592653589793" effort="100" velocity="100"/>
   </joint>
   <joint type="fixed" name="L_Wrist_z_offset">
      <parent link="L_Wrist_z_jointbody"/>
      <child link="L_Wrist"/>
      <origin xyz="-0.0 -0.0 -0.0" rpy="0.0 0.0 0.0"/>
   </joint>
   <link name="L_Hand">
      <inertial>
         <origin xyz="-0.0058 0.0493 0.001" rpy="0.0 0.0 0.0"/>
         <mass value="0.39781872"/>
         <inertia ixx="0.00048691552659360014" iyy="0.0004169246270592" izz="0.0008376325101456" ixy="0" ixz="0" iyz="0"/>
      </inertial>
   </link>
   <link name="L_Hand_x_jointbody">
      <inertial>
         <origin xyz="0.0 0.0 0.0" rpy="0.0 0.0 0.0"/>
         <mass value="0.001"/>
         <inertia ixx="1e-09" iyy="1e-09" izz="1e-09" ixy="0" ixz="0" iyz="0"/>
      </inertial>
   </link>
   <joint type="revolute" name="L_Hand_x">
      <parent link="L_Wrist"/>
      <child link="L_Hand_x_jointbody"/>
      <origin xyz="-0.0149 0.084 -0.0082" rpy="0.0 0.0 0.0"/>
      <axis xyz="1.0 0.0 0.0"/>
      <limit lower="-3.141592653589793" upper="3.141592653589793" effort="100" velocity="100"/>
   </joint>
   <link name="L_Hand_y_jointbody">
      <inertial>
         <origin xyz="0.0 0.0 0.0" rpy="0.0 0.0 0.0"/>
         <mass value="0.001"/>
         <inertia ixx="1e-09" iyy="1e-09" izz="1e-09" ixy="0" ixz="0" iyz="0"/>
      </inertial>
   </link>
   <joint type="revolute" name="L_Hand_y">
      <parent link="L_Hand_x_jointbody"/>
      <child link="L_Hand_y_jointbody"/>
      <origin xyz="0.0 0.0 0.0" rpy="0.0 0.0 0.0"/>
      <axis xyz="0.0 1.0 0.0"/>
      <limit lower="-3.141592653589793" upper="3.141592653589793" effort="100" velocity="100"/>
   </joint>
   <link name="L_Hand_z_jointbody">
      <inertial>
         <origin xyz="0.0 0.0 0.0" rpy="0.0 0.0 0.0"/>
         <mass value="0.001"/>
         <inertia ixx="1e-09" iyy="1e-09" izz="1e-09" ixy="0" ixz="0" iyz="0"/>
      </inertial>
   </link>
   <joint type="revolute" name="L_Hand_z">
      <parent link="L_Hand_y_jointbody"/>
      <child link="L_Hand_z_jointbody"/>
      <origin xyz="0.0 0.0 0.0" rpy="0.0 0.0 0.0"/>
      <axis xyz="0.0 0.0 1.0"/>
      <limit lower="-3.141592653589793" upper="3.141592653589793" effort="100" velocity="100"/>
   </joint>
   <joint type="fixed" name="L_Hand_z_offset">
      <parent link="L_Hand_z_jointbody"/>
      <child link="L_Hand"/>
      <origin xyz="-0.0 -0.0 -0.0" rpy="0.0 0.0 0.0"/>
   </joint>
   <link name="R_Thorax">
      <inertial>
         <origin xyz="-0.00455 -0.047999999999999994 0.01625" rpy="-1.8972270342276314 0.09019835940994025 -0.12568255431570874"/>
         <mass value="1.0598149119899918"/>
         <inertia ixx="0.002241310700083603" iyy="0.002241310700083603" izz="0.0012377533412274828" ixy="0" ixz="0" iyz="0"/>
      </inertial>
   </link>
   <link name="R_Thorax_x_jointbody">
      <inertial>
         <origin xyz="0.0 0.0 0.0" rpy="0.0 0.0 0.0"/>
         <mass value="0.001"/>
         <inertia ixx="1e-09" iyy="1e-09" izz="1e-09" ixy="0" ixz="0" iyz="0"/>
      </inertial>
   </link>
   <joint type="revolute" name="R_Thorax_x">
      <parent link="Chest"/>
      <child link="R_Thorax_x_jointbody"/>
      <origin xyz="-0.0386 -0.0818 0.1188" rpy="0.0 0.0 0.0"/>
      <axis xyz="1.0 0.0 0.0"/>
      <limit lower="-3.141592653589793" upper="3.141592653589793" effort="100" velocity="100"/>
   </joint>
   <link name="R_Thorax_y_jointbody">
      <inertial>
         <origin xyz="0.0 0.0 0.0" rpy="0.0 0.0 0.0"/>
         <mass value="0.001"/>
         <inertia ixx="1e-09" iyy="1e-09" izz="1e-09" ixy="0" ixz="0" iyz="0"/>
      </inertial>
   </link>
   <joint type="revolute" name="R_Thorax_y">
      <parent link="R_Thorax_x_jointbody"/>
      <child link="R_Thorax_y_jointbody"/>
      <origin xyz="0.0 0.0 0.0" rpy="0.0 0.0 0.0"/>
      <axis xyz="0.0 1.0 0.0"/>
      <limit lower="-3.141592653589793" upper="3.141592653589793" effort="100" velocity="100"/>
   </joint>
   <link name="R_Thorax_z_jointbody">
      <inertial>
         <origin xyz="0.0 0.0 0.0" rpy="0.0 0.0 0.0"/>
         <mass value="0.001"/>
         <inertia ixx="1e-09" iyy="1e-09" izz="1e-09" ixy="0" ixz="0" iyz="0"/>
      </inertial>
   </link>
   <joint type="revolute" name="R_Thorax_z">
      <parent link="R_Thorax_y_jointbody"/>
      <child link="R_Thorax_z_jointbody"/>
      <origin xyz="0.0 0.0 0.0" rpy="0.0 0.0 0.0"/>
      <axis xyz="0.0 0.0 1.0"/>
      <limit lower="-3.141592653589793" upper="3.141592653589793" effort="100" velocity="100"/>
   </joint>
   <joint type="fixed" name="R_Thorax_z_offset">
      <parent link="R_Thorax_z_jointbody"/>
      <child link="R_Thorax"/>
      <origin xyz="-0.0 -0.0 -0.0" rpy="0.0 0.0 0.0"/>
   </joint>
   <link name="R_Shoulder">
      <inertial>
         <origin xyz="-0.010700000000000001 -0.12685000000000002 -0.006699999999999999" rpy="-1.5183166528528838 0.08373270260908905 -0.07945446246584453"/>
         <mass value="1.9828441571938917"/>
         <inertia ixx="0.009892897810565678" iyy="0.009892897810565678" izz="0.002618591462157511" ixy="0" ixz="0" iyz="0"/>
      </inertial>
   </link>
   <link name="R_Shoulder_x_jointbody">
      <inertial>
         <origin xyz="0.0 0.0 0.0" rpy="0.0 0.0 0.0"/>
         <mass value="0.001"/>
         <inertia ixx="1e-09" iyy="1e-09" izz="1e-09" ixy="0" ixz="0" iyz="0"/>
      </inertial>
   </link>
   <joint type="revolute" name="R_Shoulder_x">
      <parent link="R_Thorax"/>
      <child link="R_Shoulder_x_jointbody"/>
      <origin xyz="-0.0091 -0.096 0.0326" rpy="0.0 0.0 0.0"/>
      <axis xyz="1.0 0.0 0.0"/>
      <limit lower="-12.566370614359172" upper="12.566370614359172" effort="100" velocity="100"/>
   </joint>
   <link name="R_Shoulder_y_jointbody">
      <inertial>
         <origin xyz="0.0 0.0 0.0" rpy="0.0 0.0 0.0"/>
         <mass value="0.001"/>
         <inertia ixx="1e-09" iyy="1e-09" izz="1e-09" ixy="0" ixz="0" iyz="0"/>
      </inertial>
   </link>
   <joint type="revolute" name="R_Shoulder_y">
      <parent link="R_Shoulder_x_jointbody"/>
      <child link="R_Shoulder_y_jointbody"/>
      <origin xyz="0.0 0.0 0.0" rpy="0.0 0.0 0.0"/>
      <axis xyz="0.0 1.0 0.0"/>
      <limit lower="-12.566370614359172" upper="12.566370614359172" effort="100" velocity="100"/>
   </joint>
   <link name="R_Shoulder_z_jointbody">
      <inertial>
         <origin xyz="0.0 0.0 0.0" rpy="0.0 0.0 0.0"/>
         <mass value="0.001"/>
         <inertia ixx="1e-09" iyy="1e-09" izz="1e-09" ixy="0" ixz="0" iyz="0"/>
      </inertial>
   </link>
   <joint type="revolute" name="R_Shoulder_z">
      <parent link="R_Shoulder_y_jointbody"/>
      <child link="R_Shoulder_z_jointbody"/>
      <origin xyz="0.0 0.0 0.0" rpy="0.0 0.0 0.0"/>
      <axis xyz="0.0 0.0 1.0"/>
      <limit lower="-12.566370614359172" upper="12.566370614359172" effort="100" velocity="100"/>
   </joint>
   <joint type="fixed" name="R_Shoulder_z_offset">
      <parent link="R_Shoulder_z_jointbody"/>
      <child link="R_Shoulder"/>
      <origin xyz="-0.0 -0.0 -0.0" rpy="0.0 0.0 0.0"/>
   </joint>
   <link name="R_Elbow">
      <inertial>
         <origin xyz="-0.0027500000000000003 -0.12764999999999999 0.0039" rpy="-1.6008330122270564 0.021541484344836936 -0.02219838167957633"/>
         <mass value="1.0856935131420289"/>
         <inertia ixx="0.004426215010116405" iyy="0.004426215010116405" izz="0.0008562868532361082" ixy="0" ixz="0" iyz="0"/>
      </inertial>
   </link>
   <link name="R_Elbow_x_jointbody">
      <inertial>
         <origin xyz="0.0 0.0 0.0" rpy="0.0 0.0 0.0"/>
         <mass value="0.001"/>
         <inertia ixx="1e-09" iyy="1e-09" izz="1e-09" ixy="0" ixz="0" iyz="0"/>
      </inertial>
   </link>
   <joint type="revolute" name="R_Elbow_x">
      <parent link="R_Shoulder"/>
      <child link="R_Elbow_x_jointbody"/>
      <origin xyz="-0.0214 -0.2537 -0.0133" rpy="0.0 0.0 0.0"/>
      <axis xyz="1.0 0.0 0.0"/>
      <limit lower="-12.566370614359172" upper="12.566370614359172" effort="100" velocity="100"/>
   </joint>
   <link name="R_Elbow_y_jointbody">
      <inertial>
         <origin xyz="0.0 0.0 0.0" rpy="0.0 0.0 0.0"/>
         <mass value="0.001"/>
         <inertia ixx="1e-09" iyy="1e-09" izz="1e-09" ixy="0" ixz="0" iyz="0"/>
      </inertial>
   </link>
   <joint type="revolute" name="R_Elbow_y">
      <parent link="R_Elbow_x_jointbody"/>
      <child link="R_Elbow_y_jointbody"/>
      <origin xyz="0.0 0.0 0.0" rpy="0.0 0.0 0.0"/>
      <axis xyz="0.0 1.0 0.0"/>
      <limit lower="-12.566370614359172" upper="12.566370614359172" effort="100" velocity="100"/>
   </joint>
   <link name="R_Elbow_z_jointbody">
      <inertial>
         <origin xyz="0.0 0.0 0.0" rpy="0.0 0.0 0.0"/>
         <mass value="0.001"/>
         <inertia ixx="1e-09" iyy="1e-09" izz="1e-09" ixy="0" ixz="0" iyz="0"/>
      </inertial>
   </link>
   <joint type="revolute" name="R_Elbow_z">
      <parent link="R_Elbow_y_jointbody"/>
      <child link="R_Elbow_z_jointbody"/>
      <origin xyz="0.0 0.0 0.0" rpy="0.0 0.0 0.0"/>
      <axis xyz="0.0 0.0 1.0"/>
      <limit lower="-12.566370614359172" upper="12.566370614359172" effort="100" velocity="100"/>
   </joint>
   <joint type="fixed" name="R_Elbow_z_offset">
      <parent link="R_Elbow_z_jointbody"/>
      <child link="R_Elbow"/>
      <origin xyz="-0.0 -0.0 -0.0" rpy="0.0 0.0 0.0"/>
   </joint>
   <link name="R_Wrist">
      <inertial>
         <origin xyz="-0.0052 -0.0423 -0.0030499999999999998" rpy="-1.498090065887366 0.12112889601420895 -0.11264602203724206"/>
         <mass value="0.3164382032683074"/>
         <inertia ixx="0.00033134768962124196" iyy="0.00033134768962124196" izz="0.0001527256571888088" ixy="0" ixz="0" iyz="0"/>
      </inertial>
   </link>
   <link name="R_Wrist_x_jointbody">
      <inertial>
         <origin xyz="0.0 0.0 0.0" rpy="0.0 0.0 0.0"/>
         <mass value="0.001"/>
         <inertia ixx="1e-09" iyy="1e-09" izz="1e-09" ixy="0" ixz="0" iyz="0"/>
      </inertial>
   </link>
   <joint type="revolute" name="R_Wrist_x">
      <parent link="R_Elbow"/>
      <child link="R_Wrist_x_jointbody"/>
      <origin xyz="-0.0056 -0.2553 0.0078" rpy="0.0 0.0 0.0"/>
      <axis xyz="1.0 0.0 0.0"/>
      <limit lower="-3.141592653589793" upper="3.141592653589793" effort="100" velocity="100"/>
   </joint>
   <link name="R_Wrist_y_jointbody">
      <inertial>
         <origin xyz="0.0 0.0 0.0" rpy="0.0 0.0 0.0"/>
         <mass value="0.001"/>
         <inertia ixx="1e-09" iyy="1e-09" izz="1e-09" ixy="0" ixz="0" iyz="0"/>
      </inertial>
   </link>
   <joint type="revolute" name="R_Wrist_y">
      <parent link="R_Wrist_x_jointbody"/>
      <child link="R_Wrist_y_jointbody"/>
      <origin xyz="0.0 0.0 0.0" rpy="0.0 0.0 0.0"/>
      <axis xyz="0.0 1.0 0.0"/>
      <limit lower="-3.141592653589793" upper="3.141592653589793" effort="100" velocity="100"/>
   </joint>
   <link name="R_Wrist_z_jointbody">
      <inertial>
         <origin xyz="0.0 0.0 0.0" rpy="0.0 0.0 0.0"/>
         <mass value="0.001"/>
         <inertia ixx="1e-09" iyy="1e-09" izz="1e-09" ixy="0" ixz="0" iyz="0"/>
      </inertial>
   </link>
   <joint type="revolute" name="R_Wrist_z">
      <parent link="R_Wrist_y_jointbody"/>
      <child link="R_Wrist_z_jointbody"/>
      <origin xyz="0.0 0.0 0.0" rpy="0.0 0.0 0.0"/>
      <axis xyz="0.0 0.0 1.0"/>
      <limit lower="-3.141592653589793" upper="3.141592653589793" effort="100" velocity="100"/>
   </joint>
   <joint type="fixed" name="R_Wrist_z_offset">
      <parent link="R_Wrist_z_jointbody"/>
      <child link="R_Wrist"/>
      <origin xyz="-0.0 -0.0 -0.0" rpy="0.0 0.0 0.0"/>
   </joint>
   <link name="R_Hand">
      <inertial>
         <origin xyz="-0.0079 -0.0462 -0.0009" rpy="0.0 0.0 0.0"/>
         <mass value="0.40760428800000004"/>
         <inertia ixx="0.00047643098939072003" iyy="0.00044158761617152007" izz="0.0008449324393619202" ixy="0" ixz="0" iyz="0"/>
      </inertial>
   </link>
   <link name="R_Hand_x_jointbody">
      <inertial>
         <origin xyz="0.0 0.0 0.0" rpy="0.0 0.0 0.0"/>
         <mass value="0.001"/>
         <inertia ixx="1e-09" iyy="1e-09" izz="1e-09" ixy="0" ixz="0" iyz="0"/>
      </inertial>
   </link>
   <joint type="revolute" name="R_Hand_x">
      <parent link="R_Wrist"/>
      <child link="R_Hand_x_jointbody"/>
      <origin xyz="-0.0103 -0.0846 -0.0061" rpy="0.0 0.0 0.0"/>
      <axis xyz="1.0 0.0 0.0"/>
      <limit lower="-3.141592653589793" upper="3.141592653589793" effort="100" velocity="100"/>
   </joint>
   <link name="R_Hand_y_jointbody">
      <inertial>
         <origin xyz="0.0 0.0 0.0" rpy="0.0 0.0 0.0"/>
         <mass value="0.001"/>
         <inertia ixx="1e-09" iyy="1e-09" izz="1e-09" ixy="0" ixz="0" iyz="0"/>
      </inertial>
   </link>
   <joint type="revolute" name="R_Hand_y">
      <parent link="R_Hand_x_jointbody"/>
      <child link="R_Hand_y_jointbody"/>
      <origin xyz="0.0 0.0 0.0" rpy="0.0 0.0 0.0"/>
      <axis xyz="0.0 1.0 0.0"/>
      <limit lower="-3.141592653589793" upper="3.141592653589793" effort="100" velocity="100"/>
   </joint>
   <link name="R_Hand_z_jointbody">
      <inertial>
         <origin xyz="0.0 0.0 0.0" rpy="0.0 0.0 0.0"/>
         <mass value="0.001"/>
         <inertia ixx="1e-09" iyy="1e-09" izz="1e-09" ixy="0" ixz="0" iyz="0"/>
      </inertial>
   </link>
   <joint type="revolute" name="R_Hand_z">
      <parent link="R_Hand_y_jointbody"/>
      <child link="R_Hand_z_jointbody"/>
      <origin xyz="0.0 0.0 0.0" rpy="0.0 0.0 0.0"/>
      <axis xyz="0.0 0.0 1.0"/>
      <limit lower="-3.141592653589793" upper="3.141592653589793" effort="100" velocity="100"/>
   </joint>
   <joint type="fixed" name="R_Hand_z_offset">
      <parent link="R_Hand_z_jointbody"/>
      <child link="R_Hand"/>
      <origin xyz="-0.0 -0.0 -0.0" rpy="0.0 0.0 0.0"/>
   </joint>
  <!-- Example transmissions to represent MJCF motors (gear ~ 500) for one joint; replicate for others as needed -->
  <transmission name="L_Hip_x_trans">
    <type>transmission_interface/SimpleTransmission</type>
    <actuator name="L_Hip_x_motor">
      <mechanicalReduction>500</mechanicalReduction>
    </actuator>
    <joint name="L_Hip_x">
      <hardwareInterface>hardware_interface/EffortJointInterface</hardwareInterface>
    </joint>
  </transmission>

</robot>
